Workbook

Sheet 附表
B1: 谭成义生活化减脂-90天拉锯战
A2: =主表!B4&"|"&主表!C5 -> 男|4-5小时/3次 | B2: 男 | C2: 运动量/次数 （每周） | D2: 碳水 （g/kg体重） | E2: 蛋白质 （g/kg体重） | F2: 脂肪 （g/kg体重） | H2: 31
A3: =B3&"|"&C3 -> 男|2-3小时/2次 | B3: 男 | C3: 2-3小时/2次 | D3: 2.2 | E3: 1.4 | F3: 0.8 | H3: 32
A4: =B4&"|"&C4 -> 男|4-5小时/3次 | B4: 男 | C4: 4-5小时/3次 | D4: 2.5 | E4: 1.6 | F4: 0.9 | H4: 33
A5: =B5&"|"&C5 -> 男|6-7小时/4次 | B5: 男 | C5: 6-7小时/4次 | D5: 3 | E5: 1.7 | F5: 1 | H5: 34
A6: =B6&"|"&C6 -> 男|8-9小时/5次 | B6: 男 | C6: 8-9小时/5次 | D6: 3.5 | E6: 1.8 | F6: 1 | H6: 35
B7: 女 | C7: 运动量/次数 （每周） | D7: 碳水 （g/kg体重） | E7: 蛋白质 （g/kg体重） | F7: 脂肪 （g/kg体重） | H7: 36
A8: =B8&"|"&C8 -> 女|2-3小时/2次 | B8: 女 | C8: 2-3小时/2次 | D8: 2 | E8: 1.4 | F8: 1 | H8: 37
A9: =B9&"|"&C9 -> 女|4-5小时/3次 | B9: 女 | C9: 4-5小时/3次 | D9: 2.2 | E9: 1.6 | F9: 1.1 | H9: 38
A10: =B10&"|"&C10 -> 女|6-7小时/4次 | B10: 女 | C10: 6-7小时/4次 | D10: 2.5 | E10: 1.7 | F10: 1.1 | H10: 39
A11: =B11&"|"&C11 -> 女|8-9小时/5次 | B11: 女 | C11: 8-9小时/5次 | D11: 3 | E11: 1.8 | F11: 1.2 | H11: 40
B12: 目标是减脂，而不是减重！！！ | H12: 41
B13: 提高碳水摄入以提高训练表现，达到更高的代谢水平！ | H13: 42
B14: 不需要刻意去计算代谢，根据性别、体重、每周训练时长、次数直接推算营养摄入！ | H14: 43
B15: 每10天称重并计算摄入、拍身材对比图，过快增加碳水、过慢减少碳水！ | H15: 44
H16: 45
H17: 46
H18: 47
H19: 48
H20: 49
H21: 50
H22: 51
H23: 52
H24: 53
H25: 54
H26: 55
H27: 56
... H201: 230

Sheet 食物库（谭师、自选）
D1: 碳水 | E1: 蛋白质 | F1: 脂肪 | G1: 备注 | H1: 碳水 | I1: 蛋白质 | J1: 脂肪
B2: 谭-燕麦（干） | C2: 100 | D2: 60 | E2: 13 | F2: 7 | G2: 燕麦植物蛋白，分解后赖氨酸含量极低，但在全蛋同时摄入的前提下 ，补足了赖氨酸短板，燕麦的植物蛋白可充分吸收。 | H2: =D2/C2 -> 0.6 | I2: =E2/C2 -> 0.13 | J2: =F2/C2 -> 0.07
B3: 谭-大米（生） | C3: 100 | D3: 78.5 | E3: 7.4 | F3: 0 | G3: 大米+肉蛋鱼虾时，植物蛋白可充分利用。脂肪0.8g，先不算。 | H3: =D3/C3 -> 0.785 | I3: =E3/C3 -> 0.074 | J3: =F3/C3 -> 0
B4: 谭-全蛋（个/44g） | C4: 1 | D4: 0.4 | E4: 7 | F4: 4 | G4: 全蛋碳水极低，谭师视频中说744，应该是口误。其中蛋白质7，脂肪4，碳水应该是0.4 单个鸡蛋亮氨酸约0.65g，一餐最大化肌肉合成的亮氨酸是2.5g-3g， 建议没有肉的一餐，至少吃4个全蛋。 | H4: =D4/C4 -> 0.4 | I4: =E4/C4 -> 7 | J4: =F4/C4 -> 4
B5: 谭-去皮去骨鸡腿（生） | C5: 100 | D5: 0 | E5: 24 | F5: 0 | G5: 鸡腿为运动肌，肌间脂肪相对鸡胸多。谭师没算，4g脂肪。 | H5: =D5/C5 -> 0 | I5: =E5/C5 -> 0.24 | J5: =F5/C5 -> 0
B6: 谭-鸡胸肉（生） | C6: 100 | D6: 0 | E6: 24 | F6: 0 | G6: 谭师没算脂肪，1g脂肪。 | H6: =D6/C6 -> 0 | I6: =E6/C6 -> 0.24 | J6: =F6/C6 -> 0
B7: 谭-牛肉（生） | C7: 100 | D7: 0 | E7: 24 | F7: 0 | H7: =D7/C7 -> 0 | I7: =E7/C7 -> 0.24 | J7: =F7/C7 -> 0
B8: 谭-虾仁（生） | C8: 100 | D8: 0 | E8: 20 | F8: 0 | H8: =D8/C8 -> 0 | I8: =E8/C8 -> 0.2 | J8: =F8/C8 -> 0
B9: 谭-龙利鱼（生） | C9: 100 | D9: 0 | E9: 18 | F9: 0 | G9: 谭师没算脂肪，2g | H9: =D9/C9 -> 0 | I9: =E9/C9 -> 0.18 | J9: =F9/C9 -> 0
B10: 谭-巴沙鱼（生） | C10: 100 | D10: 0 | E10: 18 | F10: 0 | G10: 谭师按18算，实际可能只有14，但影响不大。谭师没算脂肪，5g。 | H10: =D10/C10 -> 0 | I10: =E10/C10 -> 0.18 | J10: =F10/C10 -> 0
B11: 谭-红薯（生） | C11: 100 | D11: 22 | E11: 0 | F11: 0 | H11: =D11/C11 -> 0.22 | I11: =E11/C11 -> 0 | J11: =F11/C11 -> 0
B12: 谭-紫薯（生） | C12: 100 | D12: 22 | E12: 0 | F12: 0 | H12: =D12/C12 -> 0.22 | I12: =E12/C12 -> 0 | J12: =F12/C12 -> 0
B13: 谭-土豆（生） | C13: 100 | D13: 22 | E13: 0 | F13: 0 | H13: =D13/C13 -> 0.22 | I13: =E13/C13 -> 0 | J13: =F13/C13 -> 0
B14: 谭-贝贝南瓜（生） | C14: 100 | D14: 22 | E14: 0 | F14: 0 | G14: 常规南瓜碳水少，贝贝南瓜个头不大，吃起来像薯类。 | H14: =D14/C14 -> 0.22 | I14: =E14/C14 -> 0 | J14: =F14/C14 -> 0
B15: 谭-坚果 | C15: 100 | D15: 0 | E15: 0 | F15: 0 | G15: 碳水18、蛋白质18、脂肪60，谭师说先不算，了解就好。 | H15: =D15/C15 -> 0 | I15: =E15/C15 -> 0 | J15: =F15/C15 -> 0
B16: 谭-橄榄油 | C16: 100 | D16: 0 | E16: 0 | F16: 100 | H16: =D16/C16 -> 0 | I16: =E16/C16 -> 0 | J16: =F16/C16 -> 1
B17: 谭-牛油果油 | C17: 100 | D17: 0 | E17: 0 | F17: 100 | H17: =D17/C17 -> 0 | I17: =E17/C17 -> 0 | J17: =F17/C17 -> 1
B18: 谭-山茶油 | C18: 100 | D18: 0 | E18: 0 | F18: 100 | H18: =D18/C18 -> 0 | I18: =E18/C18 -> 0 | J18: =F18/C18 -> 1
B19: 谭-低芥酸菜籽油 | C19: 100 | D19: 0 | E19: 0 | F19: 100 | H19: =D19/C19 -> 0 | I19: =E19/C19 -> 0 | J19: =F19/C19 -> 1
B20: 谭-猪油 | C20: 100 | D20: 0 | E20: 0 | F20: 100 | H20: =D20/C20 -> 0 | I20: =E20/C20 -> 0 | J20: =F20/C20 -> 1
B21: 谭-牛油 | C21: 100 | D21: 0 | E21: 0 | F21: 100 | H21: =D21/C21 -> 0 | I21: =E21/C21 -> 0 | J21: =F21/C21 -> 1
B22: 谭-蓝莓 | C22: 100 | D22: 0 | E22: 0 | F22: 0 | G22: 新手减脂可先不算 | H22: =D22/C22 -> 0 | I22: =E22/C22 -> 0 | J22: =F22/C22 -> 0
B23: 谭-南瓜籽 | C23: 100 | D23: 0 | E23: 0 | F23: 0 | G23: 新手减脂可先不算 | H23: =D23/C23 -> 0 | I23: =E23/C23 -> 0 | J23: =F23/C23 -> 0
B24: 谭-蔬菜 | C24: 100 | D24: 0 | E24: 0 | F24: 0 | G24: 谭师说蔬菜都可以忽略 | H24: =D24/C24 -> 0 | I24: =E24/C24 -> 0 | J24: =F24/C24 -> 0
B25: 谭-西兰花 | C25: 100 | D25: 0 | E25: 0 | F25: 0 | H25: =D25/C25 -> 0 | I25: =E25/C25 -> 0 | J25: =F25/C25 -> 0
B26: 谭-羽衣甘蓝 | C26: 100 | D26: 0 | E26: 0 | F26: 0 | H26: =D26/C26 -> 0 | I26: =E26/C26 -> 0 | J26: =F26/C26 -> 0
B27: 谭-苋菜 | C27: 100 | D27: 0 | E27: 0 | F27: 0 | G27: 谭师说蔬菜都可以忽略 | H27: =D27/C27 -> 0 | I27: =E27/C27 -> 0 | J27: =F27/C27 -> 0
B28: 谭-菠菜 | C28: 100 | D28: 0 | E28: 0 | F28: 0 | G28: 谭师说蔬菜都可以忽略 | H28: =D28/C28 -> 0 | I28: =E28/C28 -> 0 | J28: =F28/C28 -> 0
B29: 谭-菇类 | C29: 100 | D29: 0 | E29: 0 | F29: 0 | G29: 谭师说蔬菜都可以忽略 | H29: =D29/C29 -> 0 | I29: =E29/C29 -> 0 | J29: =F29/C29 -> 0
B30: 谭-萝卜 | C30: 100 | D30: 0 | E30: 0 | F30: 0 | G30: 谭师说蔬菜都可以忽略 | H30: =D30/C30 -> 0 | I30: =E30/C30 -> 0 | J30: =F30/C30 -> 0
B31: 谭-西红柿 | C31: 100 | D31: 0 | E31: 0 | F31: 0 | G31: 谭师说蔬菜都可以忽略 | H31: =D31/C31 -> 0 | I31: =E31/C31 -> 0 | J31: =F31/C31 -> 0
B32: 谭-彩椒 | C32: 100 | D32: 0 | E32: 0 | F32: 0 | G32: 谭师说蔬菜都可以忽略 | H32: =D32/C32 -> 0 | I32: =E32/C32 -> 0 | J32: =F32/C32 -> 0
B33: 无 | C33: 100 | D33: 0 | E33: 0 | F33: 0 | G33: 很多食物中，含量少营养要素的被忽略了 谭师是为了让大家好计算、坚持下去 后续考虑更新精细版 | H33: =D33/C33 -> 0 | I33: =E33/C33 -> 0 | J33: =F33/C33 -> 0
B34: 自选-熟米饭 | C34: 100 | D34: 25.9 | E34: 2.6 | F34: 0.3 | G34: 数据来源-豆包 | H34: =D34/C34 -> 0.259 | I34: =E34/C34 -> 0.026 | J34: =F34/C34 -> 0.003
B35: 自选-馒头（熟） | C35: 100 | D35: 47 | E35: 7 | F35: 1.1 | H35: =D35/C35 -> 0.47 | I35: =E35/C35 -> 0.07 | J35: =F35/C35 -> 0.011
B36: 自选-糙米（生） | C36: 100 | D36: 76 | E36: 7.7 | F36: 2.7 | H36: =D36/C36 -> 0.76 | I36: =E36/C36 -> 0.077 | J36: =F36/C36 -> 0.027
B37: 自选-芋头（生） | C37: 100 | D37: 18.1 | E37: 2.2 | F37: 0.2 | H37: =D37/C37 -> 0.181 | I37: =E37/C37 -> 0.022 | J37: =F37/C37 -> 0.002
B38: 自选-藜麦（生） | C38: 100 | D38: 64.2 | E38: 14.1 | F38: 6.1 | H38: =D38/C38 -> 0.642 | I38: =E38/C38 -> 0.141 | J38: =F38/C38 -> 0.061
B39: 自选-猪里脊（生） | C39: 100 | D39: 0 | E39: 20.2 | F39: 7.9 | H39: =D39/C39 -> 0 | I39: =E39/C39 -> 0.202 | J39: =F39/C39 -> 0.079
B40: 自选-鳕鱼（生） | C40: 100 | D40: 0 | E40: 18 | F40: 0.7 | H40: =D40/C40 -> 0 | I40: =E40/C40 -> 0.18 | J40: =F40/C40 -> 0.007
...

Sheet 主表
A1: 原作者：谭成义——三个月生活化减脂拉锯战
A2: 减脂大法师（抖音号：DuanCengGuoYiAo) 免费制作分享 | E2: 粉丝群不定期更新版本 （20260811-V2.0）
A3: 使用人 | B3: XXX | C3: 运动时长/每周运动次数 这是对过去训练强度、训练时长、频次的一个总结，并非当前计划值、也非未来目标值。不建议初次跟练减脂计划的朋友将此值设置过高，导致拿不到正反馈而陷入迷茫焦虑。 谭师定义的一次训练（约90分钟） 2-3个热身动作4-6组，4-5个正式动作16-30组,共计18-36组。
A4: 性别 | B4: 男
A5: 体重（kg） | B5: 65 | C5: 4-5小时/3次
A6: 运动时长 （每周） | D6: 碳水 （g/kg体重） | E6: 蛋白质 （g/kg体重） | F6: 脂肪 （g/kg体重）
A7: =C5 -> 4-5小时/3次 | D7: =VLOOKUP(A45,附表!A3:F11,4) -> 2.5 | E7: =VLOOKUP(A45,附表!A3:F11,5) -> 1.6 | F7: =VLOOKUP(A45,附表!A3:F11,6) -> 0.9
A8: 调节系数（正增，负减，0为不变） 男碳水每档差额参考：0.3、0.5、0.5、0.5 女碳水每档差额参考：0.2、0.3、0.5、0.5 初始全部填“0”即可，休息日和复称时填写 休息日：男碳水2.2、女碳水2.0 | D8: 0 | E8: 0 | F8: 0
A9: 营养素调节结果 | D9: =D7+D8 -> 2.5 | E9: =E7+E8 -> 1.6 | F9: =F7+F8 -> 0.9
A10: 每日摄入建议（g） | D10: 碳水 | E10: 蛋白质 | F10: 脂肪
D11: =$B$5*D9 -> 162.5 | E11: =$B$5*E9 -> 104 | F11: =$B$5*F9 -> 58.5
A12: 早餐 | B12: 谭-燕麦（干） | C12: 95 | D12: =IFERROR(VLOOKUP(B12,'食物库（谭师、自选）'!$B$1:$J$999,7,0),0)*C12 -> 57 | E12: =IFERROR(VLOOKUP(B12,'食物库（谭师、自选）'!$B$1:$J$999,8,0),0)*C12 -> 12.35 | F12: =IFERROR(VLOOKUP(B12,'食物库（谭师、自选）'!$B$1:$J$999,9,0),0)*C12 -> 6.65
B13: 谭-全蛋（个/44g） | C13: 3 | D13: =IFERROR(VLOOKUP(B13,'食物库（谭师、自选）'!$B$1:$J$999,7,0),0)*C13 -> 1.2 | E13: =IFERROR(VLOOKUP(B13,'食物库（谭师、自选）'!$B$1:$J$999,8,0),0)*C13 -> 21 | F13: =IFERROR(VLOOKUP(B13,'食物库（谭师、自选）'!$B$1:$J$999,9,0),0)*C13 -> 12
B14: 谭-南瓜籽 | C14: 15 | D14: =IFERROR(VLOOKUP(B14,'食物库（谭师、自选）'!$B$1:$J$999,7,0),0)*C14 -> 0 | E14: =IFERROR(VLOOKUP(B14,'食物库（谭师、自选）'!$B$1:$J$999,8,0),0)*C14 -> 0 | F14: =IFERROR(VLOOKUP(B14,'食物库（谭师、自选）'!$B$1:$J$999,9,0),0)*C14 -> 0
B15: 谭-蓝莓 | C15: 100 | D15: =IFERROR(VLOOKUP(B15,'食物库（谭师、自选）'!$B$1:$J$999,7,0),0)*C15 -> 0 | E15: =IFERROR(VLOOKUP(B15,'食物库（谭师、自选）'!$B$1:$J$999,8,0),0)*C15 -> 0 | F15: =IFERROR(VLOOKUP(B15,'食物库（谭师、自选）'!$B$1:$J$999,9,0),0)*C15 -> 0
D16: =IFERROR(VLOOKUP(B16,'食物库（谭师、自选）'!$B$1:$J$999,7,0),0)*C16 -> 0 | E16: =IFERROR(VLOOKUP(B16,'食物库（谭师、自选）'!$B$1:$J$999,8,0),0)*C16 -> 0 | F16: =IFERROR(VLOOKUP(B16,'食物库（谭师、自选）'!$B$1:$J$999,9,0),0)*C16 -> 0
B17: 早餐小计 | D17: =SUM(D12:D16) -> 58.2 | E17: =SUM(E12:E16) -> 33.35 | F17: =SUM(F12:F16) -> 18.65
A18: 加餐 | D18: =IFERROR(VLOOKUP(B18,'食物库（谭师、自选）'!$B$1:$J$999,7,0),0)*C18 -> 0 | E18: =IFERROR(VLOOKUP(B18,'食物库（谭师、自选）'!$B$1:$J$999,8,0),0)*C18 -> 0 | F18: =IFERROR(VLOOKUP(B18,'食物库（谭师、自选）'!$B$1:$J$999,9,0),0)*C18 -> 0
D19: =IFERROR(VLOOKUP(B19,'食物库（谭师、自选）'!$B$1:$J$999,7,0),0)*C19 -> 0 | E19: =IFERROR(VLOOKUP(B19,'食物库（谭师、自选）'!$B$1:$J$999,8,0),0)*C19 -> 0 | F19: =IFERROR(VLOOKUP(B19,'食物库（谭师、自选）'!$B$1:$J$999,9,0),0)*C19 -> 0
D20: =IFERROR(VLOOKUP(B20,'食物库（谭师、自选）'!$B$1:$J$999,7,0),0)*C20 -> 0 | E20: =IFERROR(VLOOKUP(B20,'食物库（谭师、自选）'!$B$1:$J$999,8,0),0)*C20 -> 0 | F20: =IFERROR(VLOOKUP(B20,'食物库（谭师、自选）'!$B$1:$J$999,9,0),0)*C20 -> 0
B21: 加餐小计 | D21: =SUM(D18:D20) -> 0 | E21: =SUM(E18:E20) -> 0 | F21: =SUM(F18:F20) -> 0
A22: 午餐 | B22: 自选-熟米饭 | C22: 200 | D22: =IFERROR(VLOOKUP(B22,'食物库（谭师、自选）'!$B$1:$J$999,7,0),0)*C22 -> 51.8 | E22: =IFERROR(VLOOKUP(B22,'食物库（谭师、自选）'!$B$1:$J$999,8,0),0)*C22 -> 5.2 | F22: =IFERROR(VLOOKUP(B22,'食物库（谭师、自选）'!$B$1:$J$999,9,0),0)*C22 -> 0.6
B23: 谭-牛肉（生） | C23: 130 | D23: =IFERROR(VLOOKUP(B23,'食物库（谭师、自选）'!$B$1:$J$999,7,0),0)*C23 -> 0 | E23: =IFERROR(VLOOKUP(B23,'食物库（谭师、自选）'!$B$1:$J$999,8,0),0)*C23 -> 31.2 | F23: =IFERROR(VLOOKUP(B23,'食物库（谭师、自选）'!$B$1:$J$999,9,0),0)*C23 -> 0
B24: 谭-橄榄油 | C24: 20 | D24: =IFERROR(VLOOKUP(B24,'食物库（谭师、自选）'!$B$1:$J$999,7,0),0)*C24 -> 0 | E24: =IFERROR(VLOOKUP(B24,'食物库（谭师、自选）'!$B$1:$J$999,8,0),0)*C24 -> 0 | F24: =IFERROR(VLOOKUP(B24,'食物库（谭师、自选）'!$B$1:$J$999,9,0),0)*C24 -> 20
B25: 谭-坚果 | C25: 20 | D25: =IFERROR(VLOOKUP(B25,'食物库（谭师、自选）'!$B$1:$J$999,7,0),0)*C25 -> 0 | E25: =IFERROR(VLOOKUP(B25,'食物库（谭师、自选）'!$B$1:$J$999,8,0),0)*C25 -> 0 | F25: =IFERROR(VLOOKUP(B25,'食物库（谭师、自选）'!$B$1:$J$999,9,0),0)*C25 -> 0
B26: 谭-蔬菜 | C26: 300 | D26: =IFERROR(VLOOKUP(B26,'食物库（谭师、自选）'!$B$1:$J$999,7,0),0)*C26 -> 0 | E26: =IFERROR(VLOOKUP(B26,'食物库（谭师、自选）'!$B$1:$J$999,8,0),0)*C26 -> 0 | F26: =IFERROR(VLOOKUP(B26,'食物库（谭师、自选）'!$B$1:$J$999,9,0),0)*C26 -> 0
B27: 午餐小计 | D27: =SUM(D22:D26) -> 51.8 | E27: =SUM(E22:E26) -> 36.4 | F27: =SUM(F22:F26) -> 20.6
A28: 加餐 | D28: =IFERROR(VLOOKUP(B28,'食物库（谭师、自选）'!$B$1:$J$999,7,0),0)*C28 -> 0 | E28: =IFERROR(VLOOKUP(B28,'食物库（谭师、自选）'!$B$1:$J$999,8,0),0)*C28 -> 0 | F28: =IFERROR(VLOOKUP(B28,'食物库（谭师、自选）'!$B$1:$J$999,9,0),0)*C28 -> 0
D29: =IFERROR(VLOOKUP(B29,'食物库（谭师、自选）'!$B$1:$J$999,7,0),0)*C29 -> 0 | E29: =IFERROR(VLOOKUP(B29,'食物库（谭师、自选）'!$B$1:$J$999,8,0),0)*C29 -> 0 | F29: =IFERROR(VLOOKUP(B29,'食物库（谭师、自选）'!$B$1:$J$999,9,0),0)*C29 -> 0
D30: =IFERROR(VLOOKUP(B30,'食物库（谭师、自选）'!$B$1:$J$999,7,0),0)*C30 -> 0 | E30: =IFERROR(VLOOKUP(B30,'食物库（谭师、自选）'!$B$1:$J$999,8,0),0)*C30 -> 0 | F30: =IFERROR(VLOOKUP(B30,'食物库（谭师、自选）'!$B$1:$J$999,9,0),0)*C30 -> 0
B31: 加餐小计 | D31: =SUM(D28:D30) -> 0 | E31: =SUM(E28:E30) -> 0 | F31: =SUM(F28:F30) -> 0
A32: 晚餐 | B32: 自选-熟米饭 | C32: 200 | D32: =IFERROR(VLOOKUP(B32,'食物库（谭师、自选）'!$B$1:$J$999,7,0),0)*C32 -> 51.8 | E32: =IFERROR(VLOOKUP(B32,'食物库（谭师、自选）'!$B$1:$J$999,8,0),0)*C32 -> 5.2 | F32: =IFERROR(VLOOKUP(B32,'食物库（谭师、自选）'!$B$1:$J$999,9,0),0)*C32 -> 0.6
B33: 谭-牛肉（生） | C33: 130 | D33: =IFERROR(VLOOKUP(B33,'食物库（谭师、自选）'!$B$1:$J$999,7,0),0)*C33 -> 0 | E33: =IFERROR(VLOOKUP(B33,'食物库（谭师、自选）'!$B$1:$J$999,8,0),0)*C33 -> 31.2 | F33: =IFERROR(VLOOKUP(B33,'食物库（谭师、自选）'!$B$1:$J$999,9,0),0)*C33 -> 0
B34: 谭-橄榄油 | C34: 18 | D34: =IFERROR(VLOOKUP(B34,'食物库（谭师、自选）'!$B$1:$J$999,7,0),0)*C34 -> 0 | E34: =IFERROR(VLOOKUP(B34,'食物库（谭师、自选）'!$B$1:$J$999,8,0),0)*C34 -> 0 | F34: =IFERROR(VLOOKUP(B34,'食物库（谭师、自选）'!$B$1:$J$999,9,0),0)*C34 -> 18
B35: 谭-坚果 | C35: 20 | D35: =IFERROR(VLOOKUP(B35,'食物库（谭师、自选）'!$B$1:$J$999,7,0),0)*C35 -> 0 | E35: =IFERROR(VLOOKUP(B35,'食物库（谭师、自选）'!$B$1:$J$999,8,0),0)*C35 -> 0 | F35: =IFERROR(VLOOKUP(B35,'食物库（谭师、自选）'!$B$1:$J$999,9,0),0)*C35 -> 0
B36: 谭-蔬菜 | C36: 300 | D36: =IFERROR(VLOOKUP(B36,'食物库（谭师、自选）'!$B$1:$J$999,7,0),0)*C36 -> 0 | E36: =IFERROR(VLOOKUP(B36,'食物库（谭师、自选）'!$B$1:$J$999,8,0),0)*C36 -> 0 | F36: =IFERROR(VLOOKUP(B36,'食物库（谭师、自选）'!$B$1:$J$999,9,0),0)*C36 -> 0
B37: 晚餐小计 | D37: =SUM(D32:D36) -> 51.8 | E37: =SUM(E32:E36) -> 36.4 | F37: =SUM(F32:F36) -> 18.6
D38: 碳水 | E38: 蛋白质 | F38: 脂肪
A39: 每日建议摄入（g） | D39: =D11 -> 162.5 | E39: =E11 -> 104 | F39: =F11 -> 58.5
A40: 全天合计（g） | D40: =D17+D21+D27+D31+D37 -> 161.8 | E40: =E17+E21+E27+E31+E37 -> 106.15 | F40: =F17+F21+F27+F31+F37 -> 57.85
...

Sheet 20260814
A1: 原作者：谭成义——三个月生活化减脂拉锯战
A2: 减脂大法师（抖音号：DuanCengGuoYiAo) 免费制作分享 | E2: 粉丝群不定期更新版本 （20260811-V2.0）
A3: 使用人 | B3: XXX | C3: 运动时长/每周运动次数 这是对过去训练强度、训练时长、频次的一个总结，并非当前计划值、也非未来目标值。不建议初次跟练减脂计划的朋友将此值设置过高，导致拿不到正反馈而陷入迷茫焦虑。 谭师定义的一次训练（约90分钟） 2-3个热身动作4-6组，4-5个正式动作16-30组,共计18-36组。
A4: 性别 | B4: 男
A5: 体重（kg） | B5: 65 | C5: 2-3小时/2次
A6: 运动时长 （每周） | D6: 碳水 （g/kg体重） | E6: 蛋白质 （g/kg体重） | F6: 脂肪 （g/kg体重）
A7: =C5 -> 2-3小时/2次 | D7: =VLOOKUP(A45,附表!A3:F11,4) -> 2.2 | E7: =VLOOKUP(A45,附表!A3:F11,5) -> 1.4 | F7: =VLOOKUP(A45,附表!A3:F11,6) -> 0.8
A8: 调节系数（正增，负减，0为不变） 男碳水每档差额参考：0.3、0.5、0.5、0.5 女碳水每档差额参考：0.2、0.3、0.5、0.5 初始全部填“0”即可，休息日和复称时填写 休息日：男碳水2.2、女碳水2.0 | D8: 0 | E8: 0 | F8: 0
A9: 营养素调节结果 | D9: =D7+D8 -> 2.2 | E9: =E7+E8 -> 1.4 | F9: =F7+F8 -> 0.8
A10: 每日摄入建议（g） | D10: 碳水 | E10: 蛋白质 | F10: 脂肪
D11: =$B$5*D9 -> 143 | E11: =$B$5*E9 -> 91 | F11: =$B$5*F9 -> 52
A12: 早餐 | B12: 谭-燕麦（干） | C12: 95 | D12: =IFERROR(VLOOKUP(B12,'食物库（谭师、自选）'!$B$1:$J$999,7,0),0)*C12 -> 57 | E12: =IFERROR(VLOOKUP(B12,'食物库（谭师、自选）'!$B$1:$J$999,8,0),0)*C12 -> 12.35 | F12: =IFERROR(VLOOKUP(B12,'食物库（谭师、自选）'!$B$1:$J$999,9,0),0)*C12 -> 6.65
B13: 谭-全蛋（个/44g） | C13: 3 | D13: =IFERROR(VLOOKUP(B13,'食物库（谭师、自选）'!$B$1:$J$999,7,0),0)*C13 -> 1.2 | E13: =IFERROR(VLOOKUP(B13,'食物库（谭师、自选）'!$B$1:$J$999,8,0),0)*C13 -> 21 | F13: =IFERROR(VLOOKUP(B13,'食物库（谭师、自选）'!$B$1:$J$999,9,0),0)*C13 -> 12
B14: 谭-南瓜籽 | C14: 15 | D14: =IFERROR(VLOOKUP(B14,'食物库（谭师、自选）'!$B$1:$J$999,7,0),0)*C14 -> 0 | E14: =IFERROR(VLOOKUP(B14,'食物库（谭师、自选）'!$B$1:$J$999,8,0),0)*C14 -> 0 | F14: =IFERROR(VLOOKUP(B14,'食物库（谭师、自选）'!$B$1:$J$999,9,0),0)*C14 -> 0
B15: 谭-蓝莓 | C15: 100 | D15: =IFERROR(VLOOKUP(B15,'食物库（谭师、自选）'!$B$1:$J$999,7,0),0)*C15 -> 0 | E15: =IFERROR(VLOOKUP(B15,'食物库（谭师、自选）'!$B$1:$J$999,8,0),0)*C15 -> 0 | F15: =IFERROR(VLOOKUP(B15,'食物库（谭师、自选）'!$B$1:$J$999,9,0),0)*C15 -> 0
D16: =IFERROR(VLOOKUP(B16,'食物库（谭师、自选）'!$B$1:$J$999,7,0),0)*C16 -> 0 | E16: =IFERROR(VLOOKUP(B16,'食物库（谭师、自选）'!$B$1:$J$999,8,0),0)*C16 -> 0 | F16: =IFERROR(VLOOKUP(B16,'食物库（谭师、自选）'!$B$1:$J$999,9,0),0)*C16 -> 0
B17: 早餐小计 | D17: =SUM(D12:D16) -> 58.2 | E17: =SUM(E12:E16) -> 33.35 | F17: =SUM(F12:F16) -> 18.65
A18: 加餐 | D18: =IFERROR(VLOOKUP(B18,'食物库（谭师、自选）'!$B$1:$J$999,7,0),0)*C18 -> 0 | E18: =IFERROR(VLOOKUP(B18,'食物库（谭师、自选）'!$B$1:$J$999,8,0),0)*C18 -> 0 | F18: =IFERROR(VLOOKUP(B18,'食物库（谭师、自选）'!$B$1:$J$999,9,0),0)*C18 -> 0
D19: =IFERROR(VLOOKUP(B19,'食物库（谭师、自选）'!$B$1:$J$999,7,0),0)*C19 -> 0 | E19: =IFERROR(VLOOKUP(B19,'食物库（谭师、自选）'!$B$1:$J$999,8,0),0)*C19 -> 0 | F19: =IFERROR(VLOOKUP(B19,'食物库（谭师、自选）'!$B$1:$J$999,9,0),0)*C19 -> 0
D20: =IFERROR(VLOOKUP(B20,'食物库（谭师、自选）'!$B$1:$J$999,7,0),0)*C20 -> 0 | E20: =IFERROR(VLOOKUP(B20,'食物库（谭师、自选）'!$B$1:$J$999,8,0),0)*C20 -> 0 | F20: =IFERROR(VLOOKUP(B20,'食物库（谭师、自选）'!$B$1:$J$999,9,0),0)*C20 -> 0
B21: 加餐小计 | D21: =SUM(D18:D20) -> 0 | E21: =SUM(E18:E20) -> 0 | F21: =SUM(F18:F20) -> 0
A22: 午餐 | B22: 自选-熟米饭 | C22: 200 | D22: =IFERROR(VLOOKUP(B22,'食物库（谭师、自选）'!$B$1:$J$999,7,0),0)*C22 -> 51.8 | E22: =IFERROR(VLOOKUP(B22,'食物库（谭师、自选）'!$B$1:$J$999,8,0),0)*C22 -> 5.2 | F22: =IFERROR(VLOOKUP(B22,'食物库（谭师、自选）'!$B$1:$J$999,9,0),0)*C22 -> 0.6
B23: 谭-牛肉（生） | C23: 130 | D23: =IFERROR(VLOOKUP(B23,'食物库（谭师、自选）'!$B$1:$J$999,7,0),0)*C23 -> 0 | E23: =IFERROR(VLOOKUP(B23,'食物库（谭师、自选）'!$B$1:$J$999,8,0),0)*C23 -> 31.2 | F23: =IFERROR(VLOOKUP(B23,'食物库（谭师、自选）'!$B$1:$J$999,9,0),0)*C23 -> 0
B24: 谭-橄榄油 | C24: 20 | D24: =IFERROR(VLOOKUP(B24,'食物库（谭师、自选）'!$B$1:$J$999,7,0),0)*C24 -> 0 | E24: =IFERROR(VLOOKUP(B24,'食物库（谭师、自选）'!$B$1:$J$999,8,0),0)*C24 -> 0 | F24: =IFERROR(VLOOKUP(B24,'食物库（谭师、自选）'!$B$1:$J$999,9,0),0)*C24 -> 20
B25: 谭-坚果 | C25: 20 | D25: =IFERROR(VLOOKUP(B25,'食物库（谭师、自选）'!$B$1:$J$999,7,0),0)*C25 -> 0 | E25: =IFERROR(VLOOKUP(B25,'食物库（谭师、自选）'!$B$1:$J$999,8,0),0)*C25 -> 0 | F25: =IFERROR(VLOOKUP(B25,'食物库（谭师、自选）'!$B$1:$J$999,9,0),0)*C25 -> 0
B26: 谭-蔬菜 | C26: 300 | D26: =IFERROR(VLOOKUP(B26,'食物库（谭师、自选）'!$B$1:$J$999,7,0),0)*C26 -> 0 | E26: =IFERROR(VLOOKUP(B26,'食物库（谭师、自选）'!$B$1:$J$999,8,0),0)*C26 -> 0 | F26: =IFERROR(VLOOKUP(B26,'食物库（谭师、自选）'!$B$1:$J$999,9,0),0)*C26 -> 0
B27: 午餐小计 | D27: =SUM(D22:D26) -> 51.8 | E27: =SUM(E22:E26) -> 36.4 | F27: =SUM(F22:F26) -> 20.6
A28: 加餐 | D28: =IFERROR(VLOOKUP(B28,'食物库（谭师、自选）'!$B$1:$J$999,7,0),0)*C28 -> 0 | E28: =IFERROR(VLOOKUP(B28,'食物库（谭师、自选）'!$B$1:$J$999,8,0),0)*C28 -> 0 | F28: =IFERROR(VLOOKUP(B28,'食物库（谭师、自选）'!$B$1:$J$999,9,0),0)*C28 -> 0
D29: =IFERROR(VLOOKUP(B29,'食物库（谭师、自选）'!$B$1:$J$999,7,0),0)*C29 -> 0 | E29: =IFERROR(VLOOKUP(B29,'食物库（谭师、自选）'!$B$1:$J$999,8,0),0)*C29 -> 0 | F29: =IFERROR(VLOOKUP(B29,'食物库（谭师、自选）'!$B$1:$J$999,9,0),0)*C29 -> 0
D30: =IFERROR(VLOOKUP(B30,'食物库（谭师、自选）'!$B$1:$J$999,7,0),0)*C30 -> 0 | E30: =IFERROR(VLOOKUP(B30,'食物库（谭师、自选）'!$B$1:$J$999,8,0),0)*C30 -> 0 | F30: =IFERROR(VLOOKUP(B30,'食物库（谭师、自选）'!$B$1:$J$999,9,0),0)*C30 -> 0
B31: 加餐小计 | D31: =SUM(D28:D30) -> 0 | E31: =SUM(E28:E30) -> 0 | F31: =SUM(F28:F30) -> 0
A32: 晚餐 | B32: 自选-熟米饭 | C32: 200 | D32: =IFERROR(VLOOKUP(B32,'食物库（谭师、自选）'!$B$1:$J$999,7,0),0)*C32 -> 51.8 | E32: =IFERROR(VLOOKUP(B32,'食物库（谭师、自选）'!$B$1:$J$999,8,0),0)*C32 -> 5.2 | F32: =IFERROR(VLOOKUP(B32,'食物库（谭师、自选）'!$B$1:$J$999,9,0),0)*C32 -> 0.6
B33: 谭-牛肉（生） | C33: 130 | D33: =IFERROR(VLOOKUP(B33,'食物库（谭师、自选）'!$B$1:$J$999,7,0),0)*C33 -> 0 | E33: =IFERROR(VLOOKUP(B33,'食物库（谭师、自选）'!$B$1:$J$999,8,0),0)*C33 -> 31.2 | F33: =IFERROR(VLOOKUP(B33,'食物库（谭师、自选）'!$B$1:$J$999,9,0),0)*C33 -> 0
B34: 谭-橄榄油 | C34: 18 | D34: =IFERROR(VLOOKUP(B34,'食物库（谭师、自选）'!$B$1:$J$999,7,0),0)*C34 -> 0 | E34: =IFERROR(VLOOKUP(B34,'食物库（谭师、自选）'!$B$1:$J$999,8,0),0)*C34 -> 0 | F34: =IFERROR(VLOOKUP(B34,'食物库（谭师、自选）'!$B$1:$J$999,9,0),0)*C34 -> 18
B35: 谭-坚果 | C35: 20 | D35: =IFERROR(VLOOKUP(B35,'食物库（谭师、自选）'!$B$1:$J$999,7,0),0)*C35 -> 0 | E35: =IFERROR(VLOOKUP(B35,'食物库（谭师、自选）'!$B$1:$J$999,8,0),0)*C35 -> 0 | F35: =IFERROR(VLOOKUP(B35,'食物库（谭师、自选）'!$B$1:$J$999,9,0),0)*C35 -> 0
B36: 谭-蔬菜 | C36: 300 | D36: =IFERROR(VLOOKUP(B36,'食物库（谭师、自选）'!$B$1:$J$999,7,0),0)*C36 -> 0 | E36: =IFERROR(VLOOKUP(B36,'食物库（谭师、自选）'!$B$1:$J$999,8,0),0)*C36 -> 0 | F36: =IFERROR(VLOOKUP(B36,'食物库（谭师、自选）'!$B$1:$J$999,9,0),0)*C36 -> 0
B37: 晚餐小计 | D37: =SUM(D32:D36) -> 51.8 | E37: =SUM(E32:E36) -> 36.4 | F37: =SUM(F32:F36) -> 18.6
D38: 碳水 | E38: 蛋白质 | F38: 脂肪
A39: 每日建议摄入（g） | D39: =D11 -> 143 | E39: =E11 -> 91 | F39: =F11 -> 52
A40: 全天合计（g） | D40: =D17+D21+D27+D31+D37 -> 161.8 | E40: =E17+E21+E27+E31+E37 -> 106.15 | F40: =F17+F21+F27+F31+F37 -> 57.85
...

Sheet 20260815
A1: 原作者：谭成义——三个月生活化减脂拉锯战
A2: 减脂大法师（抖音号：DuanCengGuoYiAo) 免费制作分享 | E2: 粉丝群不定期更新版本 （20260811-V2.0）
A3: 使用人 | B3: XXX | C3: 运动时长/每周运动次数 这是对过去训练强度、训练时长、频次的一个总结，并非当前计划值、也非未来目标值。不建议初次跟练减脂计划的朋友将此值设置过高，导致拿不到正反馈而陷入迷茫焦虑。 谭师定义的一次训练（约90分钟） 2-3个热身动作4-6组，4-5个正式动作16-30组,共计18-36组。
A4: 性别 | B4: 男
A5: 体重（kg） | B5: 65 | C5: 4-5小时/3次
A6: 运动时长 （每周） | D6: 碳水 （g/kg体重） | E6: 蛋白质 （g/kg体重） | F6: 脂肪 （g/kg体重）
A7: =C5 -> 4-5小时/3次 | D7: =VLOOKUP(A45,附表!A3:F11,4) -> 2.5 | E7: =VLOOKUP(A45,附表!A3:F11,5) -> 1.6 | F7: =VLOOKUP(A45,附表!A3:F11,6) -> 0.9
A8: 调节系数（正增，负减，0为不变） 男碳水每档差额参考：0.3、0.5、0.5、0.5 女碳水每档差额参考：0.2、0.3、0.5、0.5 初始全部填“0”即可，休息日和复称时填写 休息日：男碳水2.2、女碳水2.0 | D8: 0 | E8: 0 | F8: 0
A9: 营养素调节结果 | D9: =D7+D8 -> 2.5 | E9: =E7+E8 -> 1.6 | F9: =F7+F8 -> 0.9
A10: 每日摄入建议（g） | D10: 碳水 | E10: 蛋白质 | F10: 脂肪
D11: =$B$5*D9 -> 162.5 | E11: =$B$5*E9 -> 104 | F11: =$B$5*F9 -> 58.5
A12: 早餐 | B12: 谭-燕麦（干） | C12: 95 | D12: =IFERROR(VLOOKUP(B12,'食物库（谭师、自选）'!$B$1:$J$999,7,0),0)*C12 -> 57 | E12: =IFERROR(VLOOKUP(B12,'食物库（谭师、自选）'!$B$1:$J$999,8,0),0)*C12 -> 12.35 | F12: =IFERROR(VLOOKUP(B12,'食物库（谭师、自选）'!$B$1:$J$999,9,0),0)*C12 -> 6.65
B13: 谭-全蛋（个/44g） | C13: 3 | D13: =IFERROR(VLOOKUP(B13,'食物库（谭师、自选）'!$B$1:$J$999,7,0),0)*C13 -> 1.2 | E13: =IFERROR(VLOOKUP(B13,'食物库（谭师、自选）'!$B$1:$J$999,8,0),0)*C13 -> 21 | F13: =IFERROR(VLOOKUP(B13,'食物库（谭师、自选）'!$B$1:$J$999,9,0),0)*C13 -> 12
B14: 谭-南瓜籽 | C14: 15 | D14: =IFERROR(VLOOKUP(B14,'食物库（谭师、自选）'!$B$1:$J$999,7,0),0)*C14 -> 0 | E14: =IFERROR(VLOOKUP(B14,'食物库（谭师、自选）'!$B$1:$J$999,8,0),0)*C14 -> 0 | F14: =IFERROR(VLOOKUP(B14,'食物库（谭师、自选）'!$B$1:$J$999,9,0),0)*C14 -> 0
B15: 谭-蓝莓 | C15: 100 | D15: =IFERROR(VLOOKUP(B15,'食物库（谭师、自选）'!$B$1:$J$999,7,0),0)*C15 -> 0 | E15: =IFERROR(VLOOKUP(B15,'食物库（谭师、自选）'!$B$1:$J$999,8,0),0)*C15 -> 0 | F15: =IFERROR(VLOOKUP(B15,'食物库（谭师、自选）'!$B$1:$J$999,9,0),0)*C15 -> 0
D16: =IFERROR(VLOOKUP(B16,'食物库（谭师、自选）'!$B$1:$J$999,7,0),0)*C16 -> 0 | E16: =IFERROR(VLOOKUP(B16,'食物库（谭师、自选）'!$B$1:$J$999,8,0),0)*C16 -> 0 | F16: =IFERROR(VLOOKUP(B16,'食物库（谭师、自选）'!$B$1:$J$999,9,0),0)*C16 -> 0
B17: 早餐小计 | D17: =SUM(D12:D16) -> 58.2 | E17: =SUM(E12:E16) -> 33.35 | F17: =SUM(F12:F16) -> 18.65
A18: 加餐 | D18: =IFERROR(VLOOKUP(B18,'食物库（谭师、自选）'!$B$1:$J$999,7,0),0)*C18 -> 0 | E18: =IFERROR(VLOOKUP(B18,'食物库（谭师、自选）'!$B$1:$J$999,8,0),0)*C18 -> 0 | F18: =IFERROR(VLOOKUP(B18,'食物库（谭师、自选）'!$B$1:$J$999,9,0),0)*C18 -> 0
D19: =IFERROR(VLOOKUP(B19,'食物库（谭师、自选）'!$B$1:$J$999,7,0),0)*C19 -> 0 | E19: =IFERROR(VLOOKUP(B19,'食物库（谭师、自选）'!$B$1:$J$999,8,0),0)*C19 -> 0 | F19: =IFERROR(VLOOKUP(B19,'食物库（谭师、自选）'!$B$1:$J$999,9,0),0)*C19 -> 0
D20: =IFERROR(VLOOKUP(B20,'食物库（谭师、自选）'!$B$1:$J$999,7,0),0)*C20 -> 0 | E20: =IFERROR(VLOOKUP(B20,'食物库（谭师、自选）'!$B$1:$J$999,8,0),0)*C20 -> 0 | F20: =IFERROR(VLOOKUP(B20,'食物库（谭师、自选）'!$B$1:$J$999,9,0),0)*C20 -> 0
B21: 加餐小计 | D21: =SUM(D18:D20) -> 0 | E21: =SUM(E18:E20) -> 0 | F21: =SUM(F18:F20) -> 0
A22: 午餐 | B22: 自选-熟米饭 | C22: 200 | D22: =IFERROR(VLOOKUP(B22,'食物库（谭师、自选）'!$B$1:$J$999,7,0),0)*C22 -> 51.8 | E22: =IFERROR(VLOOKUP(B22,'食物库（谭师、自选）'!$B$1:$J$999,8,0),0)*C22 -> 5.2 | F22: =IFERROR(VLOOKUP(B22,'食物库（谭师、自选）'!$B$1:$J$999,9,0),0)*C22 -> 0.6
B23: 谭-牛肉（生） | C23: 130 | D23: =IFERROR(VLOOKUP(B23,'食物库（谭师、自选）'!$B$1:$J$999,7,0),0)*C23 -> 0 | E23: =IFERROR(VLOOKUP(B23,'食物库（谭师、自选）'!$B$1:$J$999,8,0),0)*C23 -> 31.2 | F23: =IFERROR(VLOOKUP(B23,'食物库（谭师、自选）'!$B$1:$J$999,9,0),0)*C23 -> 0
B24: 谭-橄榄油 | C24: 20 | D24: =IFERROR(VLOOKUP(B24,'食物库（谭师、自选）'!$B$1:$J$999,7,0),0)*C24 -> 0 | E24: =IFERROR(VLOOKUP(B24,'食物库（谭师、自选）'!$B$1:$J$999,8,0),0)*C24 -> 0 | F24: =IFERROR(VLOOKUP(B24,'食物库（谭师、自选）'!$B$1:$J$999,9,0),0)*C24 -> 20
B25: 谭-坚果 | C25: 20 | D25: =IFERROR(VLOOKUP(B25,'食物库（谭师、自选）'!$B$1:$J$999,7,0),0)*C25 -> 0 | E25: =IFERROR(VLOOKUP(B25,'食物库（谭师、自选）'!$B$1:$J$999,8,0),0)*C25 -> 0 | F25: =IFERROR(VLOOKUP(B25,'食物库（谭师、自选）'!$B$1:$J$999,9,0),0)*C25 -> 0
B26: 谭-蔬菜 | C26: 300 | D26: =IFERROR(VLOOKUP(B26,'食物库（谭师、自选）'!$B$1:$J$999,7,0),0)*C26 -> 0 | E26: =IFERROR(VLOOKUP(B26,'食物库（谭师、自选）'!$B$1:$J$999,8,0),0)*C26 -> 0 | F26: =IFERROR(VLOOKUP(B26,'食物库（谭师、自选）'!$B$1:$J$999,9,0),0)*C26 -> 0
B27: 午餐小计 | D27: =SUM(D22:D26) -> 51.8 | E27: =SUM(E22:E26) -> 36.4 | F27: =SUM(F22:F26) -> 20.6
A28: 加餐 | D28: =IFERROR(VLOOKUP(B28,'食物库（谭师、自选）'!$B$1:$J$999,7,0),0)*C28 -> 0 | E28: =IFERROR(VLOOKUP(B28,'食物库（谭师、自选）'!$B$1:$J$999,8,0),0)*C28 -> 0 | F28: =IFERROR(VLOOKUP(B28,'食物库（谭师、自选）'!$B$1:$J$999,9,0),0)*C28 -> 0
D29: =IFERROR(VLOOKUP(B29,'食物库（谭师、自选）'!$B$1:$J$999,7,0),0)*C29 -> 0 | E29: =IFERROR(VLOOKUP(B29,'食物库（谭师、自选）'!$B$1:$J$999,8,0),0)*C29 -> 0 | F29: =IFERROR(VLOOKUP(B29,'食物库（谭师、自选）'!$B$1:$J$999,9,0),0)*C29 -> 0
D30: =IFERROR(VLOOKUP(B30,'食物库（谭师、自选）'!$B$1:$J$999,7,0),0)*C30 -> 0 | E30: =IFERROR(VLOOKUP(B30,'食物库（谭师、自选）'!$B$1:$J$999,8,0),0)*C30 -> 0 | F30: =IFERROR(VLOOKUP(B30,'食物库（谭师、自选）'!$B$1:$J$999,9,0),0)*C30 -> 0
B31: 加餐小计 | D31: =SUM(D28:D30) -> 0 | E31: =SUM(E28:E30) -> 0 | F31: =SUM(F28:F30) -> 0
A32: 晚餐 | B32: 自选-熟米饭 | C32: 200 | D32: =IFERROR(VLOOKUP(B32,'食物库（谭师、自选）'!$B$1:$J$999,7,0),0)*C32 -> 51.8 | E32: =IFERROR(VLOOKUP(B32,'食物库（谭师、自选）'!$B$1:$J$999,8,0),0)*C32 -> 5.2 | F32: =IFERROR(VLOOKUP(B32,'食物库（谭师、自选）'!$B$1:$J$999,9,0),0)*C32 -> 0.6
B33: 谭-牛肉（生） | C33: 130 | D33: =IFERROR(VLOOKUP(B33,'食物库（谭师、自选）'!$B$1:$J$999,7,0),0)*C33 -> 0 | E33: =IFERROR(VLOOKUP(B33,'食物库（谭师、自选）'!$B$1:$J$999,8,0),0)*C33 -> 31.2 | F33: =IFERROR(VLOOKUP(B33,'食物库（谭师、自选）'!$B$1:$J$999,9,0),0)*C33 -> 0
B34: 谭-橄榄油 | C34: 18 | D34: =IFERROR(VLOOKUP(B34,'食物库（谭师、自选）'!$B$1:$J$999,7,0),0)*C34 -> 0 | E34: =IFERROR(VLOOKUP(B34,'食物库（谭师、自选）'!$B$1:$J$999,8,0),0)*C34 -> 0 | F34: =IFERROR(VLOOKUP(B34,'食物库（谭师、自选）'!$B$1:$J$999,9,0),0)*C34 -> 18
B35: 谭-坚果 | C35: 20 | D35: =IFERROR(VLOOKUP(B35,'食物库（谭师、自选）'!$B$1:$J$999,7,0),0)*C35 -> 0 | E35: =IFERROR(VLOOKUP(B35,'食物库（谭师、自选）'!$B$1:$J$999,8,0),0)*C35 -> 0 | F35: =IFERROR(VLOOKUP(B35,'食物库（谭师、自选）'!$B$1:$J$999,9,0),0)*C35 -> 0
B36: 谭-蔬菜 | C36: 300 | D36: =IFERROR(VLOOKUP(B36,'食物库（谭师、自选）'!$B$1:$J$999,7,0),0)*C36 -> 0 | E36: =IFERROR(VLOOKUP(B36,'食物库（谭师、自选）'!$B$1:$J$999,8,0),0)*C36 -> 0 | F36: =IFERROR(VLOOKUP(B36,'食物库（谭师、自选）'!$B$1:$J$999,9,0),0)*C36 -> 0
B37: 晚餐小计 | D37: =SUM(D32:D36) -> 51.8 | E37: =SUM(E32:E36) -> 36.4 | F37: =SUM(F32:F36) -> 18.6
D38: 碳水 | E38: 蛋白质 | F38: 脂肪
A39: 每日建议摄入（g） | D39: =D11 -> 162.5 | E39: =E11 -> 104 | F39: =F11 -> 58.5
A40: 全天合计（g） | D40: =D17+D21+D27+D31+D37 -> 161.8 | E40: =E17+E21+E27+E31+E37 -> 106.15 | F40: =F17+F21+F27+F31+F37 -> 57.85
...

Sheet 右键主表创建副本，即可按日记录
